<mujoco model="brainco-lefthand-v2">

  <compiler angle="radian" autolimits="true" discardvisual="false"/>
  <option timestep="0.005" integrator="RK4" iterations="10" ls_iterations="10">
    <flag eulerdamp="enable"/>
  </option>

  <custom>
    <numeric data="30" name="max_contact_points"/>
    <numeric data="12" name="max_geom_pairs"/>
  </custom>

  <default>
    <default class="lefthand">
      <joint damping="0.5" armature="0.01" frictionloss="0.1"/>
      <default class="visual_hand">
        <geom group="1" type="mesh" contype="0" conaffinity="0" density="0"/>
      </default>
    </default>
  </default>

  <asset>
    <material name="silver" rgba="0.9 0.9 0.9 1"/>
    <material name="touch" rgba="0.53 0.81 0.92 1"/>

    <mesh name="left_base_link" file="meshes/left_base_link.STL"/>
    <mesh name="left_base_visual_link" file="meshes/left_base_visual_link.STL"/>
    <mesh name="left_thumb_metacarpal_link" file="meshes/left_thumb_metacarpal_link.STL"/>
    <mesh name="left_thumb_proximal_link" file="meshes/left_thumb_proximal_link.STL"/>
    <mesh name="left_thumb_proximal_visual_link" file="meshes/left_thumb_proximal_visual_link.STL"/>
    <mesh name="left_thumb_distal_link" file="meshes/left_thumb_distal_link.STL"/>
    <mesh name="left_thumb_touch_link" file="meshes/left_thumb_touch_link.STL"/>
    <mesh name="left_index_proximal_link" file="meshes/left_index_proximal_link.STL"/>
    <mesh name="left_index_distal_link" file="meshes/left_index_distal_link.STL"/>
    <mesh name="left_index_touch_link" file="meshes/left_index_touch_link.STL"/>
    <mesh name="left_middle_proximal_link" file="meshes/left_middle_proximal_link.STL"/>
    <mesh name="left_middle_distal_link" file="meshes/left_middle_distal_link.STL"/>
    <mesh name="left_middle_touch_link" file="meshes/left_middle_touch_link.STL"/>
    <mesh name="left_ring_proximal_link" file="meshes/left_ring_proximal_link.STL"/>
    <mesh name="left_ring_distal_link" file="meshes/left_ring_distal_link.STL"/>
    <mesh name="left_ring_touch_link" file="meshes/left_ring_touch_link.STL"/>
    <mesh name="left_pinky_proximal_link" file="meshes/left_pinky_proximal_link.STL"/>
    <mesh name="left_pinky_distal_link" file="meshes/left_pinky_distal_link.STL"/>
    <mesh name="left_pinky_touch_link" file="meshes/left_pinky_touch_link.STL"/>
  </asset>

  <contact>
    <exclude body1="left_base_link" body2="left_thumb_metacarpal_link"/>
    <exclude body1="left_base_link" body2="left_thumb_proximal_link"/>
    <exclude body1="left_base_link" body2="left_index_proximal_link"/>
    <exclude body1="left_base_link" body2="left_middle_proximal_link"/>
    <exclude body1="left_base_link" body2="left_ring_proximal_link"/>
    <exclude body1="left_base_link" body2="left_pinky_proximal_link"/>
  </contact>

  <worldbody>
  <body name="left_base_link" pos="0 0 0" quat="1 0 0 -1" childclass="lefthand">
<!--      <joint name="floating_base_joint" type="free"/>-->
    <geom type="mesh" contype="0" conaffinity="0" group="1" density="0" rgba="1 1 1 1" mesh="left_base_link"/>
    <geom type="mesh" contype="0" conaffinity="0" group="1" density="0" rgba="1 1 1 1" mesh="left_base_visual_link"/>
    <geom type="mesh" rgba="1 1 1 1" mesh="left_base_link"/>
    <body name="left_thumb_metacarpal_link" pos="0.0045 -0.019 0.027825" quat="0.99648 0 0 0.0838365">
      <inertial pos="1.52304e-05 -0.0070724 -0.0042084" quat="0.882814 0.0586739 -0.0302438 0.465061" mass="0.01" diaginertia="1.66114e-07 1.56005e-07 4.93864e-08"/>
      <joint name="left_thumb_metacarpal_joint" pos="0 0 0" axis="0 0 1" range="0 1.57" actuatorfrcrange="-0.5 0.5"/>
      <geom type="mesh" contype="0" conaffinity="0" group="1" density="0" rgba="1 1 1 1" mesh="left_thumb_metacarpal_link"/>
      <geom type="mesh" rgba="1 1 1 1" mesh="left_thumb_metacarpal_link"/>
      <body name="left_thumb_proximal_link" pos="0 -0.014227 0" quat="0.986557 -0.0765206 0.124804 -0.0726253">
        <inertial pos="-3.69149e-07 -0.0277016 -0.00202668" quat="0.503512 0.49651 -0.496419 0.50351" mass="0.05" diaginertia="2.56296e-06 2.40451e-06 5.11892e-07"/>
        <joint name="left_thumb_proximal_joint" pos="0 0 0" axis="-1 0 0" range="0 1.03" actuatorfrcrange="-1.1 1.1"/>
        <geom type="mesh" contype="0" conaffinity="0" group="1" density="0" rgba="1 1 1 1" mesh="left_thumb_proximal_link"/>
        <geom type="mesh" contype="0" conaffinity="0" group="1" density="0" rgba="1 1 1 1" mesh="left_thumb_proximal_visual_link"/>
        <geom type="mesh" rgba="1 1 1 1" mesh="left_thumb_proximal_link"/>
        <body name="left_thumb_distal_link" pos="0 -0.052 0">
          <inertial pos="1.60632e-07 -0.011755 1.13715e-05" quat="0.469581 0.528672 -0.528503 0.46977" mass="0.012" diaginertia="4.42098e-07 3.35619e-07 2.27749e-07"/>
          <joint name="left_thumb_distal_joint" pos="0 0 0" axis="-1 0 0" range="0 1.03" actuatorfrcrange="-1.1 1.1"/>
          <geom type="mesh" contype="0" conaffinity="0" group="1" density="0" rgba="1 1 1 1" mesh="left_thumb_distal_link"/>
          <geom type="mesh" rgba="1 1 1 1" mesh="left_thumb_distal_link"/>
          <geom pos="0 -0.013836 0.0076686" quat="0.99618 0.0873286 0 0" type="mesh" contype="0" conaffinity="0" group="1" density="0" material="touch" mesh="left_thumb_touch_link"/>
          <geom pos="0 -0.013836 0.0076686" quat="0.99618 0.0873286 0 0" type="mesh" material="touch" mesh="left_thumb_touch_link"/>
        </body>
      </body>
    </body>
    <body name="left_index_proximal_link" pos="-0.0021349 -0.029578 0.080876" quat="0.992147 0.0522807 0.0783652 0.0822789">
      <inertial pos="-0.00223539 -3.80545e-06 0.0176439" quat="0.999799 -0.000616966 0.0200059 -0.000754874" mass="0.009" diaginertia="2.52119e-07 2.36343e-07 9.27846e-08"/>
      <joint name="left_index_proximal_joint" pos="0 0 0" axis="0 1 0" range="0 1.41" actuatorfrcrange="-2 2"/>
      <geom type="mesh" contype="0" conaffinity="0" group="1" density="0" rgba="1 1 1 1" mesh="left_index_proximal_link"/>
      <geom type="mesh" rgba="1 1 1 1" mesh="left_index_proximal_link"/>
      <body name="left_index_distal_link" pos="0 0 0.032">
        <inertial pos="0.00506249 5.29762e-08 0.0165189" quat="0.684726 0.176497 0.176494 0.684725" mass="0.011" diaginertia="7.85565e-07 7.71543e-07 8.7333e-08"/>
        <joint name="left_index_distal_joint" pos="0 0 0" axis="0 1 0" range="0 1.63" actuatorfrcrange="-2 2"/>
        <geom type="mesh" contype="0" conaffinity="0" group="1" density="0" rgba="1 1 1 1" mesh="left_index_distal_link"/>
        <geom type="mesh" rgba="1 1 1 1" mesh="left_index_distal_link"/>
        <geom pos="0.014497 0 0.023303" quat="0.971859 0 0.235565 0" type="mesh" contype="0" conaffinity="0" group="1" density="0" material="touch" mesh="left_index_touch_link"/>
        <geom pos="0.014497 0 0.023303" quat="0.971859 0 0.235565 0" type="mesh" material="touch" mesh="left_index_touch_link"/>
      </body>
    </body>
    <body name="left_middle_proximal_link" pos="-0.0045935 -0.010061 0.084993" quat="0.996681 0.0175235 0.0746069 0.0274369">
      <inertial pos="-0.00222419 -3.61991e-06 0.020305" quat="0.999816 -0.000555887 0.019164 -0.000888931" mass="0.009" diaginertia="3.6726e-07 3.52522e-07 1.11867e-07"/>
      <joint name="left_middle_proximal_joint" pos="0 0 0" axis="0 1 0" range="0 1.41" actuatorfrcrange="-2 2"/>
      <geom type="mesh" contype="0" conaffinity="0" group="1" density="0" rgba="1 1 1 1" mesh="left_middle_proximal_link"/>
      <geom type="mesh" rgba="1 1 1 1" mesh="left_middle_proximal_link"/>
      <body name="left_middle_distal_link" pos="0 0 0.037" quat="0.997999 0 0.0632278 0">
        <inertial pos="0.00346095 -2.38806e-08 0.0196735" quat="0.696456 0.122525 0.12254 0.696362" mass="0.011" diaginertia="1.06829e-06 1.04939e-06 1.1141e-07"/>
        <joint name="left_middle_distal_joint" pos="0 0 0" axis="0 1 0" range="0 1.63" actuatorfrcrange="-2 2"/>
        <geom type="mesh" contype="0" conaffinity="0" group="1" density="0" rgba="1 1 1 1" mesh="left_middle_distal_link"/>
        <geom type="mesh" rgba="1 1 1 1" mesh="left_middle_distal_link"/>
        <geom pos="0.012493 0 0.028393" quat="0.984807 0 0.17365 0" type="mesh" contype="0" conaffinity="0" group="1" density="0" material="touch" mesh="left_middle_touch_link"/>
        <geom pos="0.012493 0 0.028393" quat="0.984807 0 0.17365 0" type="mesh" material="touch" mesh="left_middle_touch_link"/>
      </body>
    </body>
    <body name="left_ring_proximal_link" pos="-0.0046877 0.010026 0.083982" quat="0.996722 -0.0175386 0.0740633 -0.0274276">
      <inertial pos="-0.00234461 -5.32058e-06 0.0191786" quat="0.999832 -0.00064229 0.0183097 -0.000744974" mass="0.009" diaginertia="3.14467e-07 2.97624e-07 1.01836e-07"/>
      <joint name="left_ring_proximal_joint" pos="0 0 0" axis="0 1 0" range="0 1.41" actuatorfrcrange="-2 2"/>
      <geom type="mesh" contype="0" conaffinity="0" group="1" density="0" rgba="1 1 1 1" mesh="left_ring_proximal_link"/>
      <geom type="mesh" rgba="1 1 1 1" mesh="left_ring_proximal_link"/>
      <body name="left_ring_distal_link" pos="0 0 0.035" quat="0.997999 0 0.0632278 0">
        <inertial pos="0.00330806 4.53539e-08 0.0191705" quat="0.696112 0.124209 0.124209 0.696112" mass="0.011" diaginertia="1.01271e-06 9.96667e-07 1.02713e-07"/>
        <joint name="left_ring_distal_joint" pos="0 0 0" axis="0 1 0" range="0 1.63" actuatorfrcrange="-2 2"/>
        <geom type="mesh" contype="0" conaffinity="0" group="1" density="0" rgba="1 1 1 1" mesh="left_ring_distal_link"/>
        <geom type="mesh" rgba="1 1 1 1" mesh="left_ring_distal_link"/>
        <geom pos="0.012028 0 0.027796" quat="0.984807 0 0.17365 0" type="mesh" contype="0" conaffinity="0" group="1" density="0" material="touch" mesh="left_ring_touch_link"/>
        <geom pos="0.012028 0 0.027796" quat="0.984807 0 0.17365 0" type="mesh" material="touch" mesh="left_ring_touch_link"/>
      </body>
    </body>
    <body name="left_pinky_proximal_link" pos="-0.0023733 0.029356 0.078694" quat="0.992245 -0.052387 0.0771065 -0.0822136">
      <inertial pos="-0.00213267 -7.0226e-06 0.016068" quat="0.999803 -0.000517111 0.0198307 -0.000287779" mass="0.009" diaginertia="1.97736e-07 1.82023e-07 8.19937e-08"/>
      <joint name="left_pinky_proximal_joint" pos="0 0 0" axis="0 1 0" range="0 1.41" actuatorfrcrange="-2 2"/>
      <geom type="mesh" contype="0" conaffinity="0" group="1" density="0" rgba="1 1 1 1" mesh="left_pinky_proximal_link"/>
      <geom type="mesh" rgba="1 1 1 1" mesh="left_pinky_proximal_link"/>
      <body name="left_pinky_distal_link" pos="0 0 0.029">
        <inertial pos="0.00473719 -1.39005e-07 0.0150047" quat="0.682047 0.186482 0.186461 0.682106" mass="0.011" diaginertia="6.20812e-07 6.0761e-07 8.19131e-08"/>
        <joint name="left_pinky_distal_joint" pos="0 0 0" axis="0 1 0" range="0 1.63" actuatorfrcrange="-2 2"/>
        <geom type="mesh" contype="0" conaffinity="0" group="1" density="0" rgba="1 1 1 1" mesh="left_pinky_distal_link"/>
        <geom type="mesh" rgba="1 1 1 1" mesh="left_pinky_distal_link"/>
        <geom pos="0.01401 0 0.021124" quat="0.971859 0 0.235565 0" type="mesh" contype="0" conaffinity="0" group="1" density="0" material="touch" mesh="left_pinky_touch_link"/>
        <geom pos="0.01401 0 0.021124" quat="0.971859 0 0.235565 0" type="mesh" material="touch" mesh="left_pinky_touch_link"/>
      </body>
    </body>
    </body>
  </worldbody>

  <actuator>
    <position name="left_thumb_metacarpal_joint" joint="left_thumb_metacarpal_joint" kp="30" kv="10" ctrlrange="0 1.51"/>
    <position name="left_thumb_proximal_joint" joint="left_thumb_proximal_joint" kp="30" kv="10" ctrlrange="0 1.04"/>
    <position name="left_index_proximal_joint" joint="left_index_proximal_joint" kp="30" kv="10" ctrlrange="0 1.46"/>
    <position name="left_middle_proximal_joint" joint="left_middle_proximal_joint" kp="30" kv="10" ctrlrange="0 1.46"/>
    <position name="left_ring_proximal_joint" joint="left_ring_proximal_joint" kp="30" kv="10" ctrlrange="0 1.46"/>
    <position name="left_pinky_proximal_joint" joint="left_pinky_proximal_joint" kp="30" kv="10" ctrlrange="0 1.46"/>
  </actuator>

  <equality>
    <!-- mimic distal -> proximal -->
    <joint joint1="left_index_proximal_joint" joint2="left_index_distal_joint" polycoef="0 1. 0 0"/>
    <joint joint1="left_middle_proximal_joint" joint2="left_middle_distal_joint" polycoef="0 1.155 0 0"/>
    <joint joint1="left_ring_proximal_joint" joint2="left_ring_distal_joint" polycoef="0 1.155 0 0"/>
    <joint joint1="left_pinky_proximal_joint" joint2="left_pinky_distal_joint" polycoef="0 1.155 0 0"/>
    <joint joint1="left_thumb_proximal_joint" joint2="left_thumb_distal_joint" polycoef="0 1.155 0 0"/>
  </equality>

</mujoco>
